<?xml version="1.0"?>
<robot xmlns:xacro="http://www.ros.org/wiki/xacro">

    <!-- TO DO <xacro:include filename="$(find articubot_two)/description/material_color.xacro" /> -->

    <!-- BASE LINK -->

    <link name="base_link">

    </link>

    <!-- CHASSIS LINK -->

    <joint name="chassis_joint" type="fixed">
        <parent link="base_link"/>
        <child link="chassis"/>
        <origin xyz="0 0 0" rpy="0 0 0"/>
    </joint>
    <link name="chassis">
        <visual>
            <origin xyz="0 0 0" rpy="0 0 0"/>
            <geometry>
                <mesh filename="package://articubot_two/meshes/chassis.stl" scale="0.001 0.001 0.001"/>
            </geometry>
            <material name="grey">
                <color rgba="0.5 0.5 0.5 1"/>
            </material>
        </visual>
        <collision>
            <geometry>
                <mesh filename="package://articubot_two/meshes/chassis.stl" scale="0.001 0.001 0.001"/>
            </geometry>
        </collision>
    </link>

    <!-- LEFT WHEEL LINK -->

    <joint name="left_wheel_joint" type="continuous">
        <parent link="base_link"/>
        <child link="left_wheel"/>
        <origin xyz="0 0.09 0.02" rpy="${-pi/2} 0 0"/>
        <axis xyz="0 0 1"/>
    </joint>
    <link name="left_wheel">
        <visual>
            <geometry>
                <mesh filename="package://articubot_two/meshes/wheel.stl" scale="0.001 0.001 0.001"/>
            </geometry>
            <material name="blue">
                <color rgba="0 0 1 1"/>
            </material>
        </visual>
        <collision>
            <geometry>
                <mesh filename="package://articubot_two/meshes/wheel.stl" scale="0.001 0.001 0.001"/>
            </geometry>
        </collision>
    </link>

    <!-- RIGHT WHEEL LINK -->

    <joint name="right_wheel_joint" type="continuous">
        <parent link="base_link"/>
        <child link="right_wheel"/>
        <origin xyz="0 -0.09 0.02" rpy="${pi/2} 0 0"/>
        <axis xyz="0 0 -1"/>
    </joint>
    <link name="right_wheel">
        <visual>
            <geometry>
                <mesh filename="package://articubot_two/meshes/wheel.stl" scale="0.001 0.001 0.001"/>
            </geometry>
            <material name="blue">
                <color rgba="0 0 1 1"/>
            </material>
        </visual>
        <collision>
            <geometry>
                <mesh filename="package://articubot_two/meshes/wheel.stl" scale="0.001 0.001 0.001"/>
            </geometry>
        </collision>
    </link>
    
    <!-- FRONT CASTER WHEEL LINK -->
    <joint name="front_caster_wheel_joint" type="fixed">
        <parent link="chassis"/>
        <child link="front_caster_wheel"/>
        <origin xyz="0.12 0 0" rpy="0 0 0"/>
    </joint>
    <link name="front_caster_wheel">
        <visual>
            <geometry>
                <sphere radius="0.015" />
            </geometry>
            <material name="red">
                <color rgba="1 0 0 1"/>
            </material>
        </visual>
        <collision>
            <geometry>
                <sphere radius="0.015" />
            </geometry>
        </collision>
    </link>

    <!-- Back CASTER WHEEL LINK -->
    <joint name="back_caster_wheel_joint" type="fixed">
        <parent link="chassis"/>
        <child link="back_caster_wheel"/>
        <origin xyz="-0.12 0 0" rpy="0 0 0"/>
    </joint>
    <link name="back_caster_wheel">
        <visual>
            <geometry>
                <sphere radius="0.015" />
            </geometry>
            <material name="red">
                <color rgba="1 0 0 1"/>
            </material>
        </visual>
        <collision>
            <geometry>
                <sphere radius="0.015" />
            </geometry>
        </collision>
    </link>

</robot>